<?xml version="1.0" ?>
<robot name="arm">
  <link name="base_link">
    <visual>
      <geometry>
        <box size="2.5 1.25 0.375"/>
      </geometry>
      <origin/>
    </visual>
    <collision>
      <geometry>
        <box size="2.5 1.25 0.375"/>
      </geometry>
      <origin/>
    </collision>
    <inertial>
      <origin rpy="0.0 0.0 0.0" xyz="0.0 0.0 0.0"/>
      <mass value="10.0"/>
      <inertia ixx="0.24739583333333334" ixy="0.0" ixz="0.0" iyy="5.325520833333334" iyz="0.0" izz="5.338541666666667"/>
    </inertial>
  </link>
  <link name="back_right_upper">
    <visual>
      <geometry>
        <box size="0.5249999999999999 0.22499999999999998 0.22499999999999998"/>
      </geometry>
      <origin rpy="0 -.25 0" xyz="-0.22499999999999998 0 0"/>
    </visual>
    <collision>
      <geometry>
        <box size="0.5249999999999999 0.22499999999999998 0.22499999999999998"/>
      </geometry>
      <origin rpy="0 -.25 0" xyz="-0.22499999999999998 0 0"/>
    </collision>
    <inertial>
      <origin rpy="0.0 0.0 0.0" xyz="0.0 0.0 0.0"/>
      <mass value="2.5"/>
      <inertia ixx="0.022265625" ixy="0.0" ixz="0.0" iyy="0.47929687500000007" iyz="0.0" izz="0.48046875"/>
    </inertial>
  </link>
  <link name="back_right_lower">
    <visual>
      <geometry>
        <box size="1.125 0.22499999999999998 0.22499999999999998"/>
      </geometry>
      <origin rpy="0 1.3 0" xyz="0 0 -0.5025000000000001 "/>
    </visual>
    <collision>
      <geometry>
        <box size="1.125 0.22499999999999998 0.22499999999999998"/>
      </geometry>
      <origin rpy="0 1.3 0" xyz="0 0 -0.5025000000000001 "/>
    </collision>
    <inertial>
      <origin rpy="0.0 0.0 0.0" xyz="0.0 0.0 0.0"/>
      <mass value="2.5"/>
      <inertia ixx="0.022265625" ixy="0.0" ixz="0.0" iyy="0.47929687500000007" iyz="0.0" izz="0.48046875"/>
    </inertial>
  </link>
  <link name="back_right_foot">
    <visual>
      <geometry>
        <box size="0.5249999999999999 0.22499999999999998 0.22499999999999998"/>
      </geometry>
      <origin rpy="0 0 0" xyz="-0.22499999999999998 0 0"/>
    </visual>
    <collision>
      <geometry>
        <box size="0.5249999999999999 0.22499999999999998 0.22499999999999998"/>
      </geometry>
      <origin rpy="0 0 0" xyz="-0.22499999999999998 0 0"/>
    </collision>
    <inertial>
      <origin rpy="0.0 0.0 0.0" xyz="0.0 0.0 0.0"/>
      <mass value="2.5"/>
      <inertia ixx="0.022265625" ixy="0.0" ixz="0.0" iyy="0.47929687500000007" iyz="0.0" izz="0.48046875"/>
    </inertial>
  </link>
  <joint name="back_right_shoulder" type="revolute">
    <parent link="base_link"/>
    <child link="back_right_upper"/>
    <limit effort="20.0" lower="-1.2" upper="1.2" velocity="20.0"/>
    <origin xyz="0.875 0.75 0"/>
    <axis xyz="0 1 0"/>
  </joint>
  <joint name="back_right_knee" type="revolute">
    <parent link="back_right_upper"/>
    <child link="back_right_lower"/>
    <limit effort="20.0" lower="-1.2" upper="1.2" velocity="20.0"/>
    <origin xyz="-0.375 0 0"/>
    <axis xyz="0 1 0"/>
  </joint>
  <joint name="back_right_ankle" type="revolute">
    <parent link="back_right_lower"/>
    <child link="back_right_foot"/>
    <limit effort="20.0" lower="-1.2" upper="1.2" velocity="20.0"/>
    <origin xyz="0.15000000000000002 0 -0.9750000000000001"/>
    <axis xyz="0 1 0"/>
  </joint>
  <link name="back_left_upper">
    <visual>
      <geometry>
        <box size="0.5249999999999999 0.22499999999999998 0.22499999999999998"/>
      </geometry>
      <origin rpy="0 -.25 0" xyz="-0.22499999999999998 0 0"/>
    </visual>
    <collision>
      <geometry>
        <box size="0.5249999999999999 0.22499999999999998 0.22499999999999998"/>
      </geometry>
      <origin rpy="0 -.25 0" xyz="-0.22499999999999998 0 0"/>
    </collision>
    <inertial>
      <origin rpy="0.0 0.0 0.0" xyz="0.0 0.0 0.0"/>
      <mass value="2.5"/>
      <inertia ixx="0.022265625" ixy="0.0" ixz="0.0" iyy="0.47929687500000007" iyz="0.0" izz="0.48046875"/>
    </inertial>
  </link>
  <link name="back_left_lower">
    <visual>
      <geometry>
        <box size="1.125 0.22499999999999998 0.22499999999999998"/>
      </geometry>
      <origin rpy="0 1.3 0" xyz="0 0 -0.5025000000000001 "/>
    </visual>
    <collision>
      <geometry>
        <box size="1.125 0.22499999999999998 0.22499999999999998"/>
      </geometry>
      <origin rpy="0 1.3 0" xyz="0 0 -0.5025000000000001 "/>
    </collision>
    <inertial>
      <origin rpy="0.0 0.0 0.0" xyz="0.0 0.0 0.0"/>
      <mass value="2.5"/>
      <inertia ixx="0.022265625" ixy="0.0" ixz="0.0" iyy="0.47929687500000007" iyz="0.0" izz="0.48046875"/>
    </inertial>
  </link>
  <link name="back_left_foot">
    <visual>
      <geometry>
        <box size="0.5249999999999999 0.22499999999999998 0.22499999999999998"/>
      </geometry>
      <origin rpy="0 0 0" xyz="-0.22499999999999998 0 0"/>
    </visual>
    <collision>
      <geometry>
        <box size="0.5249999999999999 0.22499999999999998 0.22499999999999998"/>
      </geometry>
      <origin rpy="0 0 0" xyz="-0.22499999999999998 0 0"/>
    </collision>
    <inertial>
      <origin rpy="0.0 0.0 0.0" xyz="0.0 0.0 0.0"/>
      <mass value="2.5"/>
      <inertia ixx="0.022265625" ixy="0.0" ixz="0.0" iyy="0.47929687500000007" iyz="0.0" izz="0.48046875"/>
    </inertial>
  </link>
  <joint name="back_left_shoulder" type="revolute">
    <parent link="base_link"/>
    <child link="back_left_upper"/>
    <limit effort="20.0" lower="-1.2" upper="1.2" velocity="20.0"/>
    <origin xyz="0.875 -0.75 0"/>
    <axis xyz="0 1 0"/>
  </joint>
  <joint name="back_left_knee" type="revolute">
    <parent link="back_left_upper"/>
    <child link="back_left_lower"/>
    <limit effort="20.0" lower="-1.2" upper="1.2" velocity="20.0"/>
    <origin xyz="-0.375 0 0"/>
    <axis xyz="0 1 0"/>
  </joint>
  <joint name="back_left_ankle" type="revolute">
    <parent link="back_left_lower"/>
    <child link="back_left_foot"/>
    <limit effort="20.0" lower="-1.2" upper="1.2" velocity="20.0"/>
    <origin xyz="0.15000000000000002 0 -0.9750000000000001"/>
    <axis xyz="0 1 0"/>
  </joint>
  <link name="front_right_upper">
    <visual>
      <geometry>
        <box size="0.5249999999999999 0.22499999999999998 0.22499999999999998"/>
      </geometry>
      <origin rpy="0 -.25 0" xyz="-0.22499999999999998 0 0"/>
    </visual>
    <collision>
      <geometry>
        <box size="0.5249999999999999 0.22499999999999998 0.22499999999999998"/>
      </geometry>
      <origin rpy="0 -.25 0" xyz="-0.22499999999999998 0 0"/>
    </collision>
    <inertial>
      <origin rpy="0.0 0.0 0.0" xyz="0.0 0.0 0.0"/>
      <mass value="2.5"/>
      <inertia ixx="0.022265625" ixy="0.0" ixz="0.0" iyy="0.47929687500000007" iyz="0.0" izz="0.48046875"/>
    </inertial>
  </link>
  <link name="front_right_lower">
    <visual>
      <geometry>
        <box size="1.125 0.22499999999999998 0.22499999999999998"/>
      </geometry>
      <origin rpy="0 1.3 0" xyz="0 0 -0.5025000000000001 "/>
    </visual>
    <collision>
      <geometry>
        <box size="1.125 0.22499999999999998 0.22499999999999998"/>
      </geometry>
      <origin rpy="0 1.3 0" xyz="0 0 -0.5025000000000001 "/>
    </collision>
    <inertial>
      <origin rpy="0.0 0.0 0.0" xyz="0.0 0.0 0.0"/>
      <mass value="2.5"/>
      <inertia ixx="0.022265625" ixy="0.0" ixz="0.0" iyy="0.47929687500000007" iyz="0.0" izz="0.48046875"/>
    </inertial>
  </link>
  <link name="front_right_foot">
    <visual>
      <geometry>
        <box size="0.5249999999999999 0.22499999999999998 0.22499999999999998"/>
      </geometry>
      <origin rpy="0 0 0" xyz="-0.22499999999999998 0 0"/>
    </visual>
    <collision>
      <geometry>
        <box size="0.5249999999999999 0.22499999999999998 0.22499999999999998"/>
      </geometry>
      <origin rpy="0 0 0" xyz="-0.22499999999999998 0 0"/>
    </collision>
    <inertial>
      <origin rpy="0.0 0.0 0.0" xyz="0.0 0.0 0.0"/>
      <mass value="2.5"/>
      <inertia ixx="0.022265625" ixy="0.0" ixz="0.0" iyy="0.47929687500000007" iyz="0.0" izz="0.48046875"/>
    </inertial>
  </link>
  <joint name="front_right_shoulder" type="revolute">
    <parent link="base_link"/>
    <child link="front_right_upper"/>
    <limit effort="20.0" lower="-1.2" upper="1.2" velocity="20.0"/>
    <origin xyz="-0.875 0.75 0"/>
    <axis xyz="0 1 0"/>
  </joint>
  <joint name="front_right_knee" type="revolute">
    <parent link="front_right_upper"/>
    <child link="front_right_lower"/>
    <limit effort="20.0" lower="-1.2" upper="1.2" velocity="20.0"/>
    <origin xyz="-0.375 0 0"/>
    <axis xyz="0 1 0"/>
  </joint>
  <joint name="front_right_ankle" type="revolute">
    <parent link="front_right_lower"/>
    <child link="front_right_foot"/>
    <limit effort="20.0" lower="-1.2" upper="1.2" velocity="20.0"/>
    <origin xyz="0.15000000000000002 0 -0.9750000000000001"/>
    <axis xyz="0 1 0"/>
  </joint>
  <link name="front_left_upper">
    <visual>
      <geometry>
        <box size="0.5249999999999999 0.22499999999999998 0.22499999999999998"/>
      </geometry>
      <origin rpy="0 -.25 0" xyz="-0.22499999999999998 0 0"/>
    </visual>
    <collision>
      <geometry>
        <box size="0.5249999999999999 0.22499999999999998 0.22499999999999998"/>
      </geometry>
      <origin rpy="0 -.25 0" xyz="-0.22499999999999998 0 0"/>
    </collision>
    <inertial>
      <origin rpy="0.0 0.0 0.0" xyz="0.0 0.0 0.0"/>
      <mass value="2.5"/>
      <inertia ixx="0.022265625" ixy="0.0" ixz="0.0" iyy="0.47929687500000007" iyz="0.0" izz="0.48046875"/>
    </inertial>
  </link>
  <link name="front_left_lower">
    <visual>
      <geometry>
        <box size="1.125 0.22499999999999998 0.22499999999999998"/>
      </geometry>
      <origin rpy="0 1.3 0" xyz="0 0 -0.5025000000000001 "/>
    </visual>
    <collision>
      <geometry>
        <box size="1.125 0.22499999999999998 0.22499999999999998"/>
      </geometry>
      <origin rpy="0 1.3 0" xyz="0 0 -0.5025000000000001 "/>
    </collision>
    <inertial>
      <origin rpy="0.0 0.0 0.0" xyz="0.0 0.0 0.0"/>
      <mass value="2.5"/>
      <inertia ixx="0.022265625" ixy="0.0" ixz="0.0" iyy="0.47929687500000007" iyz="0.0" izz="0.48046875"/>
    </inertial>
  </link>
  <link name="front_left_foot">
    <visual>
      <geometry>
        <box size="0.5249999999999999 0.22499999999999998 0.22499999999999998"/>
      </geometry>
      <origin rpy="0 0 0" xyz="-0.22499999999999998 0 0"/>
    </visual>
    <collision>
      <geometry>
        <box size="0.5249999999999999 0.22499999999999998 0.22499999999999998"/>
      </geometry>
      <origin rpy="0 0 0" xyz="-0.22499999999999998 0 0"/>
    </collision>
    <inertial>
      <origin rpy="0.0 0.0 0.0" xyz="0.0 0.0 0.0"/>
      <mass value="2.5"/>
      <inertia ixx="0.022265625" ixy="0.0" ixz="0.0" iyy="0.47929687500000007" iyz="0.0" izz="0.48046875"/>
    </inertial>
  </link>
  <joint name="front_left_shoulder" type="revolute">
    <parent link="base_link"/>
    <child link="front_left_upper"/>
    <limit effort="20.0" lower="-1.2" upper="1.2" velocity="20.0"/>
    <origin xyz="-0.875 -0.75 0"/>
    <axis xyz="0 1 0"/>
  </joint>
  <joint name="front_left_knee" type="revolute">
    <parent link="front_left_upper"/>
    <child link="front_left_lower"/>
    <limit effort="20.0" lower="-1.2" upper="1.2" velocity="20.0"/>
    <origin xyz="-0.375 0 0"/>
    <axis xyz="0 1 0"/>
  </joint>
  <joint name="front_left_ankle" type="revolute">
    <parent link="front_left_lower"/>
    <child link="front_left_foot"/>
    <limit effort="20.0" lower="-1.2" upper="1.2" velocity="20.0"/>
    <origin xyz="0.15000000000000002 0 -0.9750000000000001"/>
    <axis xyz="0 1 0"/>
  </joint>
</robot>
