<?xml version="1.0"?>
<robot xmlns:xacro="http://www.ros.org/wiki/xacro" name="arm">

<xacro:property name="total_weight" value="20" /> <!--KG-->
<xacro:property name="torso_weight" value="${total_weight * 0.5}" />
<xacro:property name="leg_weight" value="${(total_weight - torso_weight) * 0.25}" />

<xacro:property name="torso_length" value="2.5"/>
<xacro:property name="leg_length" value="1.5"/>

<xacro:macro name="solid_sphere_inertia_tensors" params="mass radius" >
    <inertial>
        <origin xyz="0.0 0.0 0.0" rpy="0.0 0.0 0.0"/>
        <mass value="${weight}"/>
        <inertia 
        ixx="${(2/5) * mass * radius * radius}" ixy="0.0" ixz="0.0" 
        iyy="${(2/5) * mass * radius * radius}" iyz="0.0" 
        izz="${(2/5) * mass * radius * radius}  "/>
    </inertial>
</xacro:macro>

<xacro:macro name="hollow_sphere_inertia_tensors" params="mass radius" >
    <inertial>
        <origin xyz="0.0 0.0 0.0" rpy="0.0 0.0 0.0"/>
        <mass value="${weight}"/>
        <inertia 
        ixx="${(2/3) * mass * radius * radius}" ixy="0.0" ixz="0.0" 
        iyy="${(2/3) * mass * radius * radius}" iyz="0.0" 
        izz="${(2/3) * mass * radius * radius}  "/>
    </inertial>
</xacro:macro>

<xacro:macro name="cuboid_inertia_tensors" params="weight length" >
    <inertial>
        <origin xyz="0.0 0.0 0.0" rpy="0.0 0.0 0.0"/>
        <mass value="${weight}"/>
        <inertia 
        ixx="${(weight/12)*((length*length*.025)+(length*length*0.0225))}" ixy="0.0" ixz="0.0" 
        iyy="${(weight/12)*((length*length)+(length*length*0.0225))}" iyz="0.0" 
        izz="${(weight/12)*((length*length)+(length*length*0.025))}"/>
    </inertial>
</xacro:macro>


ixx ixy ixz
    iyy iyz
        izz














<xacro:macro name="joint_ball" params="name offset">
    <link name="${name}">
        <visual>
            <geometry>
                <sphere radius="0.01"/>
            </geometry>
            <origin xyz="${offset}"/>
        </visual>
        <collision>
            <geometry>
                <sphere radius="0.01"/>
            </geometry>
            <origin xyz="${offset}"/>
        </collision>
    </link>
</xacro:macro>

<xacro:macro name="limb" params="name length offset rpy">
    <link name="${name}">
        <visual>
            <geometry>
                <cylinder radius="0.0050" length="${length}"/>
            </geometry>
            <origin xyz="${offset}" rpy="${rpy}"/>
        </visual>
        <collision>
            <geometry>
                <cylinder radius="0.0050" length="${length}"/>
            </geometry>
            <origin xyz="${offset}" rpy="${rpy}"/>
        </collision>
    </link>

</xacro:macro>

<xacro:macro name="affix" params="name parent child">
    <joint name="${name}" type="fixed">
        <parent link="${parent}"/>
        <child link="${child}"/>
    </joint>
</xacro:macro>

<xacro:macro name="revolve" params="name parent child hi lo axis offset">
    <joint name="${name}" type="revolute">
        <parent link="${parent}"/>
        <child link="${child}"/>
        <limit lower="${lo}" upper="${hi}" effort="20.0" velocity="20.0"/>
        <origin xyz="${offset}"/>
        <axis xyz="${axis}"/>
    </joint>
</xacro:macro>


<xacro:joint_ball name="base_link" offset="0 0 0"/>
<!-- Limbs-->


<!-- Fixed Joints-->

<!-- Revolute Joints-->


</robot>
